[32m2024-10-05 00:29:05 +0530[0m - dagster - [34mDEBUG[0m - __ASSET_JOB - efb8e82b-2ebe-46a0-a727-3cb9edf7511c - 5491 - LOGS_CAPTURED - Started capturing logs in process (pid: 5491).
[32m2024-10-05 00:29:05 +0530[0m - dagster - [34mDEBUG[0m - __ASSET_JOB - efb8e82b-2ebe-46a0-a727-3cb9edf7511c - 5491 - mongodb - STEP_START - Started execution of step "mongodb".
[32m2024-10-05 00:29:05 +0530[0m - dagster - [34mERROR[0m - [31m__ASSET_JOB - efb8e82b-2ebe-46a0-a727-3cb9edf7511c - 5491 - mongodb - STEP_FAILURE - Execution of step "mongodb" failed.

dagster._core.errors.DagsterExecutionStepExecutionError: Error occurred while executing op "mongodb"::

dlt.pipeline.exceptions.PipelineStepFailed: Pipeline execution failed at stage sync with exception:

<class 'dlt.common.configuration.exceptions.ConfigurationValueError'>
Please specify password or private_key or authenticator fields. SnowflakeCredentials supports password, private key and authenticator based (ie. oauth2) authentication and one of those must be specified.

Stack Trace:
  File "/Users/surajnag/anaconda3/envs/dagster-mflix/lib/python3.11/site-packages/dagster/_core/execution/plan/utils.py", line 54, in op_execution_error_boundary
    yield
  File "/Users/surajnag/anaconda3/envs/dagster-mflix/lib/python3.11/site-packages/dagster/_utils/__init__.py", line 482, in iterate_with_context
    next_output = next(iterator)
                  ^^^^^^^^^^^^^^
  File "/Users/surajnag/Documents/dagster-project/dagster_project/assets/mongodb.py", line 25, in dlt_asset_factory
    yield from dlt.run(context=context, write_disposition="merge")
  File "/Users/surajnag/anaconda3/envs/dagster-mflix/lib/python3.11/site-packages/dagster_embedded_elt/dlt/resource.py", line 166, in run
    load_info = dlt_pipeline.run(dlt_source, **kwargs)
                ^^^^^^^^^^^^^^^^^^^^^^^^^^^^^^^^^^^^^^
  File "/Users/surajnag/anaconda3/envs/dagster-mflix/lib/python3.11/site-packages/dlt/pipeline/pipeline.py", line 223, in _wrap
    step_info = f(self, *args, **kwargs)
                ^^^^^^^^^^^^^^^^^^^^^^^^
  File "/Users/surajnag/anaconda3/envs/dagster-mflix/lib/python3.11/site-packages/dlt/pipeline/pipeline.py", line 268, in _wrap
    return f(self, *args, **kwargs)
           ^^^^^^^^^^^^^^^^^^^^^^^^
  File "/Users/surajnag/anaconda3/envs/dagster-mflix/lib/python3.11/site-packages/dlt/pipeline/pipeline.py", line 681, in run
    self.sync_destination(destination, staging, dataset_name)
  File "/Users/surajnag/anaconda3/envs/dagster-mflix/lib/python3.11/site-packages/dlt/pipeline/pipeline.py", line 177, in _wrap
    rv = f(self, *args, **kwargs)
         ^^^^^^^^^^^^^^^^^^^^^^^^
  File "/Users/surajnag/anaconda3/envs/dagster-mflix/lib/python3.11/site-packages/dlt/pipeline/pipeline.py", line 811, in sync_destination
    raise PipelineStepFailed(self, "sync", None, ex, None) from ex

The above exception was caused by the following exception:
dlt.common.configuration.exceptions.ConfigurationValueError: Please specify password or private_key or authenticator fields. SnowflakeCredentials supports password, private key and authenticator based (ie. oauth2) authentication and one of those must be specified.

Stack Trace:
  File "/Users/surajnag/anaconda3/envs/dagster-mflix/lib/python3.11/site-packages/dlt/pipeline/pipeline.py", line 742, in sync_destination
    remote_state = self._restore_state_from_destination()
                   ^^^^^^^^^^^^^^^^^^^^^^^^^^^^^^^^^^^^^^
  File "/Users/surajnag/anaconda3/envs/dagster-mflix/lib/python3.11/site-packages/dlt/pipeline/pipeline.py", line 1483, in _restore_state_from_destination
    with self._get_destination_clients(schema)[0] as job_client:
         ^^^^^^^^^^^^^^^^^^^^^^^^^^^^^^^^^^^^^
  File "/Users/surajnag/anaconda3/envs/dagster-mflix/lib/python3.11/site-packages/dlt/pipeline/pipeline.py", line 1244, in _get_destination_clients
    client = self.destination.client(schema, initial_config)
             ^^^^^^^^^^^^^^^^^^^^^^^^^^^^^^^^^^^^^^^^^^^^^^^
  File "/Users/surajnag/anaconda3/envs/dagster-mflix/lib/python3.11/site-packages/dlt/common/destination/reference.py", line 748, in client
    config = self.configuration(initial_config)
             ^^^^^^^^^^^^^^^^^^^^^^^^^^^^^^^^^^
  File "/Users/surajnag/anaconda3/envs/dagster-mflix/lib/python3.11/site-packages/dlt/common/destination/reference.py", line 735, in configuration
    config = resolve_configuration(
             ^^^^^^^^^^^^^^^^^^^^^^
  File "/Users/surajnag/anaconda3/envs/dagster-mflix/lib/python3.11/site-packages/dlt/common/configuration/resolve.py", line 67, in resolve_configuration
    return _resolve_configuration(config, sections, (), explicit_value, accept_partial)
           ^^^^^^^^^^^^^^^^^^^^^^^^^^^^^^^^^^^^^^^^^^^^^^^^^^^^^^^^^^^^^^^^^^^^^^^^^^^^
  File "/Users/surajnag/anaconda3/envs/dagster-mflix/lib/python3.11/site-packages/dlt/common/configuration/resolve.py", line 164, in _resolve_configuration
    _resolve_config_fields(
  File "/Users/surajnag/anaconda3/envs/dagster-mflix/lib/python3.11/site-packages/dlt/common/configuration/resolve.py", line 264, in _resolve_config_fields
    current_value, traces = _resolve_config_field(
                            ^^^^^^^^^^^^^^^^^^^^^^
  File "/Users/surajnag/anaconda3/envs/dagster-mflix/lib/python3.11/site-packages/dlt/common/configuration/resolve.py", line 387, in _resolve_config_field
    value = _resolve_configuration(
            ^^^^^^^^^^^^^^^^^^^^^^^
  File "/Users/surajnag/anaconda3/envs/dagster-mflix/lib/python3.11/site-packages/dlt/common/configuration/resolve.py", line 168, in _resolve_configuration
    config.resolve()
  File "/Users/surajnag/anaconda3/envs/dagster-mflix/lib/python3.11/site-packages/dlt/common/configuration/specs/base_configuration.py", line 374, in resolve
    self.call_method_in_mro("on_resolved")
  File "/Users/surajnag/anaconda3/envs/dagster-mflix/lib/python3.11/site-packages/dlt/common/configuration/specs/base_configuration.py", line 439, in call_method_in_mro
    c.__dict__[method_name](config)
  File "/Users/surajnag/anaconda3/envs/dagster-mflix/lib/python3.11/site-packages/dlt/destinations/impl/snowflake/configuration.py", line 88, in on_resolved
    raise ConfigurationValueError(
[0m
